<?xml version="1.0"?>

<robot name="ebamk2">

<!-- BASE LINK -->
  <link
    name="base_link">
    <visual>
      <origin xyz="0 0 0" rpy="0 0 0" />
      <geometry>
        <mesh filename="package://ebamk2_description/meshes/base_link.STL" />
      </geometry>
      <material name="">
        <color rgba="1 0 0 1" />
      </material>
    </visual>
    <collision>
      <geometry>
        <cylinder length="0.0001" radius="0.0001"/>
      </geometry>
      <origin rpy="0 0 0" xyz="0 0 0"/>
    </collision>
  </link>

<!-- JOINT 1 HIP-->
  <joint name="joint_1" type="revolute">
    <origin xyz="0 0 0.05" rpy="0 0 0" />
    <parent link="base_link" />
    <child link="link_1" />
    <axis xyz="0 0 1" />
    <limit effort="0" velocity="0"
      lower="-0.7854" upper="0.7854"/>
  </joint>

<!-- LINK 1 HIP-->
  <link
    name="link_1">
    <visual>
      <origin
        xyz="0 -0.04 0" rpy="0 0 0" />
      <geometry>
        <mesh filename="package://ebamk2_description/meshes/link_1.STL" />
      </geometry>
      <material name="">
        <color rgba="0 0.275 0 1" />
      </material>
    </visual>
  </link>

<!-- JOINT 2 SHOULDER -->
  <joint name="joint_2" type="revolute">
    <origin xyz="0 -0.005 0.037" rpy="1.578 0 0" />
    <parent link="link_1" />
    <child link="link_2" />
    <axis xyz="0 0 1" />
    <limit effort="0" velocity="0"
      lower="-0.80" upper="0.35"/>
  </joint>

<!-- LINK 2 SHOULDER -->
  <link name="link_2">
    <visual>
      <origin xyz="0 0 0.0075" rpy="3.14159 0 0" />
      <geometry>
        <mesh filename="package://ebamk2_description/meshes/link_2.STL" />
      </geometry>
      <material name="">
        <color rgba="0 0 1 1" />
      </material>
    </visual>
  </link>

  <!-- VIRTUAL MIMIC JOINT 2-->
  <!--
  <joint name="joint2v" type="revolute">
    <origin xyz="-0.021 0.135 -0.0105" rpy="1.570796325 0 0" />
    <parent link="link_2"/>
    <child link="link_2v"/>
    <axis xyz="0 1 0"/>
    <limit effort="30" velocity="1.0" lower="-3.14159" upper="3.14159" />
    <mimic joint="joint_2" multiplier="-1" offset="0" />
  </joint>

  <link name="link_2v">
    <visual>
      <geometry>
        <cylinder length="0.001" radius="0.0001"/>
      </geometry>
      <material name="">
        <color rgba="0 0 0 0" />
      </material>
      <origin rpy="0 0 0" xyz="0 0 0"/>
    </visual>
    <collision>
      <geometry>
        <cylinder length="0.0001" radius="0.0001"/>
      </geometry>
      <origin rpy="0 0 0" xyz="0 0 0"/>
    </collision>
  </link>
-->
<!-- JOINT 3 ELBOW -->
  <joint name="joint_3" type="revolute">
    <!--<axis xyz="0 1 0" />
    <origin xyz="0 0 0" rpy="0 0 0" />
    <parent link="link_2v" />-->
    <axis xyz="0 0 1" />
    <origin xyz="-0.021 0.133 -0.0105" rpy="0 0 0" />
    <parent link="link_2" />
    <child link="link_3" />
    <limit effort="0" velocity="0"
      lower="-0.77" upper="0.45"/>
  </joint>

  <!-- LINK 3 ELBOW -->
   <link name="link_3">
    <visual>
      <!--<origin xyz="0 0.0335 0.002" rpy="1.570796325 0 0" />-->
      <origin xyz="0 0 0.0335" rpy="3.14159 0 0.1309" />
      <geometry>
        <mesh filename="package://ebamk2_description/meshes/link_3.STL" />
      </geometry>
      <material name="">
        <color rgba="1 0 0 1" />
      </material>
    </visual>
  </link>

  <!-- JOINT 4 CLAW SUPPORT -->
  <joint name="joint_4" type="revolute">
    <!--<origin xyz="0.1459 0.0185 0.0203" rpy="0 1.570796325 3.14159" />-->
    <origin xyz="0.147 0 0.018" rpy="-1.570796325 0 1.570796325" />
    <parent link="link_3" />
    <child link="link_4" />
    <axis xyz="0 1 0" />
    <limit effort="0" velocity="0" lower="-3.14159" upper="3.14159"/>
    <!--<mimic joint="joint_3" multiplier="1" offset="0" />-->
  </joint>

  <!-- LINK 4 CLAW SUPPORT -->
  <link name="link_4">
    <visual>
      <!--<origin xyz="-0.006 0 -0.0394" rpy="0 0 0" />-->
      <origin xyz="-0.006 0 -0.0394" rpy="0 0 0" />
      <geometry>
        <mesh filename="package://ebamk2_description/meshes/link_4.STL" scale="0.001 0.001 0.001" />
      </geometry>
      <material name="">
        <color rgba="0 0.275 0 1" />
      </material>  
    </visual>
  </link>

  <!-- JOINT 5 CLAW BASE -->
  <joint name="joint_5" type="fixed">
    <origin xyz="-0.0095 0.001 -0.033" rpy="-0 1.570796325 0" />
    <parent link="link_4" />
    <child link="claw_base" />
    <axis xyz="1 0 0" />
  </joint>

  <!-- LINK 4 CLAW BASE -->
  <link name="claw_base">
    <visual>
      <origin xyz="0 0 0" rpy="0 0 0" />
      <geometry>
        <mesh filename="package://ebamk2_description/meshes/link_5.STL" scale="0.001 0.001 0.001" />
      </geometry>
      <material name="">
        <color rgba="0 0 1 1" />
      </material>
    </visual>
  </link>

  <!-- FINGERS -->
  <joint name="joint_6" type="revolute">
    <origin xyz="0.0196 0.021 -0.004" rpy="0 0 0" />
    <parent link="claw_base"/>
    <child link="claw_l"/>
    <axis xyz="0 0 1" />
    <limit effort="0" lower="0" upper="0.65" velocity="1.0" />
  </joint>

  <joint name="joint_7" type="revolute">
    <origin xyz="0.0196 0.0040 -0.004" rpy="0 0 0" />
    <parent link="claw_base"/>
    <child link="claw_r"/>
    <axis xyz="0 0 -1" />
    <limit effort="0" lower="0" upper="0.65" velocity="1.0" />
    <mimic joint="joint_6" multiplier="1.0" offset="0" />
  </joint>

  <link name="claw_l">
    <visual>
      <origin xyz="0.0505 0.000 0" rpy="0 0 2.9" />
      <geometry>
        <mesh filename="package://ebamk2_description/meshes/claw_l.STL" scale="0.001 0.001 0.001" />
      </geometry>
    </visual>
  </link>

  <link name="claw_r">
    <visual>
      <origin xyz="0.0488 0.0102 0" rpy="0 0 3.14159" />
      <geometry>
        <mesh filename="package://ebamk2_description/meshes/claw_r.STL" scale="0.001 0.001 0.001" />
      </geometry>
    </visual>
  </link>

  <!-- TRANSMISSIONS -->
  <transmission name="trans_1">
    <type>transmission_interface/SimpleTransmission</type>
    <joint name="joint_1">
      <hardwareInterface>PositionJointInterface</hardwareInterface>
    </joint>
    <actuator name="servo1">
      <hardwareInterface>PositionJointInterface</hardwareInterface>
      <mechanicalReduction>1</mechanicalReduction>
    </actuator>
  </transmission>
  <transmission name="trans_2">
    <type>transmission_interface/SimpleTransmission</type>
    <joint name="joint_2">
      <hardwareInterface>PositionJointInterface</hardwareInterface>
    </joint>
    <actuator name="servo2">
      <hardwareInterface>PositionJointInterface</hardwareInterface>
      <mechanicalReduction>1</mechanicalReduction>
    </actuator>
  </transmission>
  <transmission name="trans_3">
    <type>transmission_interface/SimpleTransmission</type>
    <joint name="joint_3">
      <hardwareInterface>PositionJointInterface</hardwareInterface>
    </joint>
    <actuator name="servo3">
      <hardwareInterface>PositionJointInterface</hardwareInterface>
      <mechanicalReduction>1</mechanicalReduction>
    </actuator>
  </transmission>
  <transmission name="trans_6">
    <type>transmission_interface/SimpleTransmission</type>
    <joint name="joint_6">
      <hardwareInterface>PositionJointInterface</hardwareInterface>
    </joint>
    <actuator name="servo4">
      <hardwareInterface>PositionJointInterface</hardwareInterface>
      <mechanicalReduction>1</mechanicalReduction>
    </actuator>
  </transmission>

</robot>
